<?xml version="1.0" encoding="UTF-8"?>
<!-- Generated by org.testng.reporters.JUnitXMLReporter -->
<testsuite ignored="3" hostname="DESKTOP-F3186QF" failures="1" tests="3" name="Default test" time="47.677" errors="0" timestamp="2019-09-18T20:53:57 ART">
  <testcase classname="test.TestAutomation" name="Login_Correcto" time="5.057"/>
  <testcase classname="test.TestAutomation" name="Login_Correcto" time="3.711">
    <failure type="java.lang.AssertionError" message="Error en caso de Datos Incorrectos! expected:&amp;lt;nUjk FtrEX&amp;gt; but was:&amp;lt;Sign in&amp;gt;">
      <![CDATA[java.lang.AssertionError: Error en caso de Datos Incorrectos! expected:<nUjk FtrEX> but was:<Sign in>
at org.testng.AssertJUnit.assertEquals(AssertJUnit.java:82)
at test.TestAutomation.Login_Correcto(TestAutomation.java:67)
at java.base/jdk.internal.reflect.NativeMethodAccessorImpl.invoke0(Native Method)
at java.base/jdk.internal.reflect.NativeMethodAccessorImpl.invoke(NativeMethodAccessorImpl.java:62)
at java.base/jdk.internal.reflect.DelegatingMethodAccessorImpl.invoke(DelegatingMethodAccessorImpl.java:43)
at java.base/java.lang.reflect.Method.invoke(Method.java:567)
at org.testng.internal.MethodInvocationHelper.invokeMethod(MethodInvocationHelper.java:133)
at org.testng.internal.TestInvoker.invokeMethod(TestInvoker.java:584)
at org.testng.internal.TestInvoker.invokeTestMethod(TestInvoker.java:172)
at org.testng.internal.MethodRunner.runInSequence(MethodRunner.java:46)
at org.testng.internal.TestInvoker$MethodInvocationAgent.invoke(TestInvoker.java:804)
at org.testng.internal.TestInvoker.invokeTestMethods(TestInvoker.java:145)
at org.testng.internal.TestMethodWorker.invokeTestMethods(TestMethodWorker.java:146)
at org.testng.internal.TestMethodWorker.run(TestMethodWorker.java:128)
at java.base/java.util.ArrayList.forEach(ArrayList.java:1507)
at org.testng.TestRunner.privateRun(TestRunner.java:770)
at org.testng.TestRunner.run(TestRunner.java:591)
at org.testng.SuiteRunner.runTest(SuiteRunner.java:402)
at org.testng.SuiteRunner.runSequentially(SuiteRunner.java:396)
at org.testng.SuiteRunner.privateRun(SuiteRunner.java:355)
at org.testng.SuiteRunner.run(SuiteRunner.java:304)
at org.testng.SuiteRunnerWorker.runSuite(SuiteRunnerWorker.java:53)
at org.testng.SuiteRunnerWorker.run(SuiteRunnerWorker.java:96)
at org.testng.TestNG.runSuitesSequentially(TestNG.java:1180)
at org.testng.TestNG.runSuitesLocally(TestNG.java:1102)
at org.testng.TestNG.runSuites(TestNG.java:1032)
at org.testng.TestNG.run(TestNG.java:1000)
at org.testng.remote.AbstractRemoteTestNG.run(AbstractRemoteTestNG.java:115)
at org.testng.remote.RemoteTestNG.initAndRun(RemoteTestNG.java:251)
at org.testng.remote.RemoteTestNG.main(RemoteTestNG.java:77)
]]>
    </failure>
  </testcase> <!-- Login_Correcto -->
  <testcase classname="test.TestAutomation" name="Login_Correcto" time="4.139"/>
  <testcase classname="test.TestAutomation" name="MessageError" time="0.0">
    <ignored/>
  </testcase> <!-- MessageError -->
  <testcase classname="test.TestAutomation" name="ControlMail" time="0.0">
    <ignored/>
  </testcase> <!-- ControlMail -->
  <testcase classname="test.TestAutomation" name="create_Account" time="0.0">
    <ignored/>
  </testcase> <!-- create_Account -->
</testsuite> <!-- Default test -->
